<!DOCTYPE html>
<html lang="en-US">
<!--********************************************-->
<!--*       Generated from PreTeXt source      *-->
<!--*       on 2022-08-10T16:19:19-04:00       *-->
<!--*   A recent stable commit (2020-08-09):   *-->
<!--* 98f21740783f166a773df4dc83cab5293ab63a4a *-->
<!--*                                          *-->
<!--*         https://pretextbook.org          *-->
<!--*                                          *-->
<!--********************************************-->
<head>
<meta http-equiv="Content-Type" content="text/html; charset=UTF-8">
<meta name="robots" content="noindex, nofollow">
</head>
<body class="ignore-math">
<h3 class="heading"><span class="type">Paragraph</span></h3>
<p>We can handle this exception by creating a divide function that can <code class="code-inline tex2jax_ignore">throw</code> an error. A corresponding <code class="code-inline tex2jax_ignore">try</code> and <code class="code-inline tex2jax_ignore">catch</code> block can “catch” the exception and prints a message back to the user in the event that an exception occurs. For example, try changing the values assigned to firstNum and secondNum in the code below:</p>
<span class="incontext"><a href="exception_-handling_exception-handling.html#p-576" class="internal">in-context</a></span>
</body>
</html>
