<!DOCTYPE html>
<html lang="en-US">
<!--********************************************-->
<!--*       Generated from PreTeXt source      *-->
<!--*       on 2022-08-10T16:19:19-04:00       *-->
<!--*   A recent stable commit (2020-08-09):   *-->
<!--* 98f21740783f166a773df4dc83cab5293ab63a4a *-->
<!--*                                          *-->
<!--*         https://pretextbook.org          *-->
<!--*                                          *-->
<!--********************************************-->
<head>
<meta http-equiv="Content-Type" content="text/html; charset=UTF-8">
<meta name="robots" content="noindex, nofollow">
</head>
<body class="ignore-math">
<h3 class="heading"><span class="type">Paragraph</span></h3>
<p>When an exception occurs, we say that it has been “thrown.” You can “catch” the exception that has been raised by using a <code class="code-inline tex2jax_ignore">try</code> statement. For example, consider the following session that asks the user for an integer and then uses the division operator. If the user enters a second number that is not 0, then the print will show the result of division. However, if the user enters 0, then C++ will throw an error and return a value other than 0.</p>
<span class="incontext"><a href="exception_-handling_exception-handling.html#p-575" class="internal">in-context</a></span>
</body>
</html>
